Workbook
Name All_Teams: OFFSET(Games!#REF!,0,0,COUNTA(Games!#REF!)-1,1)
Name Method: Games!#REF!
Name SeedInfo: Games!#REF!
Name SeedType: Games!#REF!
Name snowball: [1]Calculator!$F$21
Name strategy: [1]Calculator!$F$20
Name valuevx: 42.314159

Sheet Teams
A1: Seed | B1: Region | C1: Team | D1: Hyperlink Name | E1: Logo
A2: 1 | B2: South | C2: Abilene Christian | D2: abilene-christian | E2: =_xlfn.IMAGE(_xlfn.CONCAT("https://cdn.ssref.net/req/202510241/tlogo/ncaa/",TEXT(Teams[[#This Row],[Hyperlink Name]],),"-2025.png")) -> #VALUE!
A3: 16 | B3: South | C3: Air Force | D3: air-force | E3: =_xlfn.IMAGE(_xlfn.CONCAT("https://cdn.ssref.net/req/202510241/tlogo/ncaa/",TEXT(Teams[[#This Row],[Hyperlink Name]],),"-2025.png")) -> #VALUE!
A4: 8 | B4: South | C4: Akron | D4: akron | E4: =_xlfn.IMAGE(_xlfn.CONCAT("https://cdn.ssref.net/req/202510241/tlogo/ncaa/",TEXT(Teams[[#This Row],[Hyperlink Name]],),"-2025.png")) -> #VALUE!
A5: 9 | B5: South | C5: Alabama | D5: alabama | E5: =_xlfn.IMAGE(_xlfn.CONCAT("https://cdn.ssref.net/req/202510241/tlogo/ncaa/",TEXT(Teams[[#This Row],[Hyperlink Name]],),"-2025.png")) -> #VALUE!
A6: 5 | B6: South | C6: Alabama A&M | D6: alabama-am | E6: =_xlfn.IMAGE(_xlfn.CONCAT("https://cdn.ssref.net/req/202510241/tlogo/ncaa/",TEXT(Teams[[#This Row],[Hyperlink Name]],),"-2025.png")) -> #VALUE!
A7: 12 | B7: South | C7: Alabama State | D7: alabama-state | E7: =_xlfn.IMAGE(_xlfn.CONCAT("https://cdn.ssref.net/req/202510241/tlogo/ncaa/",TEXT(Teams[[#This Row],[Hyperlink Name]],),"-2025.png")) -> #VALUE!
A8: 4 | B8: South | C8: Albany (NY) | D8: albany-ny | E8: =_xlfn.IMAGE(_xlfn.CONCAT("https://cdn.ssref.net/req/202510241/tlogo/ncaa/",TEXT(Teams[[#This Row],[Hyperlink Name]],),"-2025.png")) -> #VALUE!
A9: 13 | B9: South | C9: Alcorn State | D9: alcorn-state | E9: =_xlfn.IMAGE(_xlfn.CONCAT("https://cdn.ssref.net/req/202510241/tlogo/ncaa/",TEXT(Teams[[#This Row],[Hyperlink Name]],),"-2025.png")) -> #VALUE!
A10: 6 | B10: South | C10: American | D10: american | E10: =_xlfn.IMAGE(_xlfn.CONCAT("https://cdn.ssref.net/req/202510241/tlogo/ncaa/",TEXT(Teams[[#This Row],[Hyperlink Name]],),"-2025.png")) -> #VALUE!
A11: 11 | B11: South | C11: Appalachian State | D11: appalachian-state | E11: =_xlfn.IMAGE(_xlfn.CONCAT("https://cdn.ssref.net/req/202510241/tlogo/ncaa/",TEXT(Teams[[#This Row],[Hyperlink Name]],),"-2025.png")) -> #VALUE!
A12: 3 | B12: South | C12: Arizona | D12: arizona | E12: =_xlfn.IMAGE(_xlfn.CONCAT("https://cdn.ssref.net/req/202510241/tlogo/ncaa/",TEXT(Teams[[#This Row],[Hyperlink Name]],),"-2025.png")) -> #VALUE!
A13: 14 | B13: South | C13: Arizona State | D13: arizona-state | E13: =_xlfn.IMAGE(_xlfn.CONCAT("https://cdn.ssref.net/req/202510241/tlogo/ncaa/",TEXT(Teams[[#This Row],[Hyperlink Name]],),"-2025.png")) -> #VALUE!
... A65: 15 | B65: Midwest | C65: Dartmouth | D65: dartmouth | E65: =_xlfn.IMAGE(_xlfn.CONCAT("https://cdn.ssref.net/req/202510241/tlogo/ncaa/",TEXT(Teams[[#This Row],[Hyperlink Name]],),"-2025.png")) -> #VALUE!

Sheet Games
G1: Tournament Picks for Multiple Players | S1: .
C3: Loser | D3: Seed Bonus | E3: Game # | F3: Seed | G3: Pairing | J3: Seed | K3: Score 1 | M3: Score 2 | O3: Winner | Q3: Evaluation
A5: =G5 -> Abilene Christian | B5: =I5 -> Air Force | C5: =IF(O5="","",IF(A5=O5,B5,A5)) -> Abilene Christian | D5: =IF(SeedType=1,0,IF(SeedType=2,VLOOKUP(O5,SeedInfo,2,FALSE)*1,MAX(VLOOKUP(O5,SeedInfo,2,FALSE)-VLOOKUP(C5,SeedInfo,2,FALSE),0))) -> #REF! | E5: 1 | F5: {=_xlfn.XLOOKUP(G5,Teams[[#All],[Team]],Teams[[#All],[Seed]],0,0,1)} -> 1 | G5: =Teams!C2 -> Abilene Christian | H5: vs | I5: =Teams!C3 -> Air Force | J5: {=_xlfn.XLOOKUP(I5,Teams[[#All],[Team]],Teams[[#All],[Seed]],0,0,1)} -> 16 | K5: =_xlfn.XLOOKUP(G5,Teams!$C:$C,Teams!$E:$E,,0,1) -> #VALUE! | L5: =RANDBETWEEN(90,120) -> 104 | M5: =_xlfn.XLOOKUP(I5,Teams!$C:$C,Teams!$E:$E,,0,1) -> #VALUE! | N5: =RANDBETWEEN(90,120) -> 111 | O5: =IF(L5>N5,G5,I5) -> Air Force | P5: =_xlfn.XLOOKUP(O5,Teams!$C:$C,Teams!$E:$E,,0,1) -> #VALUE! | R5: =IF( O5=G5, IF(F5>J5,TRUE,FALSE), IF(J5>F5,TRUE,FALSE)) -> TRUE
A6: =G6 -> Akron | B6: =I6 -> Alabama | C6: =IF(O6="","",IF(A6=O6,B6,A6)) -> Akron | D6: =IF(SeedType=1,0,IF(SeedType=2,VLOOKUP(O6,SeedInfo,2,FALSE)*1,MAX(VLOOKUP(O6,SeedInfo,2,FALSE)-VLOOKUP(C6,SeedInfo,2,FALSE),0))) -> #REF! | E6: 2 | F6: {=_xlfn.XLOOKUP(G6,Teams[[#All],[Team]],Teams[[#All],[Seed]],0,0,1)} -> 8 | G6: =Teams!C4 -> Akron | H6: vs | I6: =Teams!C5 -> Alabama | J6: {=_xlfn.XLOOKUP(I6,Teams[[#All],[Team]],Teams[[#All],[Seed]],0,0,1)} -> 9 | K6: =_xlfn.XLOOKUP(G6,Teams!$C:$C,Teams!$E:$E,,0,1) -> #VALUE! | L6: =RANDBETWEEN(90,120) -> 111 | M6: =_xlfn.XLOOKUP(I6,Teams!$C:$C,Teams!$E:$E,,0,1) -> #VALUE! | N6: =RANDBETWEEN(90,120) -> 120 | O6: =IF(L6>N6,G6,I6) -> Alabama | P6: =_xlfn.XLOOKUP(O6,Teams!$C:$C,Teams!$E:$E,,0,1) -> #VALUE! | R6: =IF( O6=G6, IF(F6>J6,TRUE,FALSE), IF(J6>F6,TRUE,FALSE)) -> TRUE
A7: =G7 -> Alabama A&M | B7: =I7 -> Alabama State | C7: =IF(O7="","",IF(A7=O7,B7,A7)) -> Alabama State | D7: =IF(SeedType=1,0,IF(SeedType=2,VLOOKUP(O7,SeedInfo,2,FALSE)*1,MAX(VLOOKUP(O7,SeedInfo,2,FALSE)-VLOOKUP(C7,SeedInfo,2,FALSE),0))) -> #REF! | E7: 3 | F7: {=_xlfn.XLOOKUP(G7,Teams[[#All],[Team]],Teams[[#All],[Seed]],0,0,1)} -> 5 | G7: =Teams!C6 -> Alabama A&M | H7: vs | I7: =Teams[[#This Row],[Team]] -> Alabama State | J7: {=_xlfn.XLOOKUP(I7,Teams[[#All],[Team]],Teams[[#All],[Seed]],0,0,1)} -> 12 | K7: =_xlfn.XLOOKUP(G7,Teams!$C:$C,Teams!$E:$E,,0,1) -> #VALUE! | L7: =RANDBETWEEN(90,120) -> 100 | M7: =_xlfn.XLOOKUP(I7,Teams!$C:$C,Teams!$E:$E,,0,1) -> #VALUE! | N7: =RANDBETWEEN(90,120) -> 97 | O7: =IF(L7>N7,G7,I7) -> Alabama A&M | P7: =_xlfn.XLOOKUP(O7,Teams!$C:$C,Teams!$E:$E,,0,1) -> #VALUE! | R7: =IF( O7=G7, IF(F7>J7,TRUE,FALSE), IF(J7>F7,TRUE,FALSE)) -> FALSE
A8: =G8 -> Albany (NY) | B8: =I8 -> Alcorn State | C8: =IF(O8="","",IF(A8=O8,B8,A8)) -> Albany (NY) | D8: =IF(SeedType=1,0,IF(SeedType=2,VLOOKUP(O8,SeedInfo,2,FALSE)*1,MAX(VLOOKUP(O8,SeedInfo,2,FALSE)-VLOOKUP(C8,SeedInfo,2,FALSE),0))) -> #REF! | E8: 4 | F8: {=_xlfn.XLOOKUP(G8,Teams[[#All],[Team]],Teams[[#All],[Seed]],0,0,1)} -> 4 | G8: =Teams[[#This Row],[Team]] -> Albany (NY) | H8: vs | I8: =Teams!C9 -> Alcorn State | J8: {=_xlfn.XLOOKUP(I8,Teams[[#All],[Team]],Teams[[#All],[Seed]],0,0,1)} -> 13 | K8: =_xlfn.XLOOKUP(G8,Teams!$C:$C,Teams!$E:$E,,0,1) -> #VALUE! | L8: =RANDBETWEEN(90,120) -> 103 | M8: =_xlfn.XLOOKUP(I8,Teams!$C:$C,Teams!$E:$E,,0,1) -> #VALUE! | N8: =RANDBETWEEN(90,120) -> 109 | O8: =IF(L8>N8,G8,I8) -> Alcorn State | P8: =_xlfn.XLOOKUP(O8,Teams!$C:$C,Teams!$E:$E,,0,1) -> #VALUE! | R8: =IF( O8=G8, IF(F8>J8,TRUE,FALSE), IF(J8>F8,TRUE,FALSE)) -> TRUE
A9: =G9 -> American | B9: =I9 -> Appalachian State | C9: =IF(O9="","",IF(A9=O9,B9,A9)) -> Appalachian State | D9: =IF(SeedType=1,0,IF(SeedType=2,VLOOKUP(O9,SeedInfo,2,FALSE)*1,MAX(VLOOKUP(O9,SeedInfo,2,FALSE)-VLOOKUP(C9,SeedInfo,2,FALSE),0))) -> #REF! | E9: 5 | F9: {=_xlfn.XLOOKUP(G9,Teams[[#All],[Team]],Teams[[#All],[Seed]],0,0,1)} -> 6 | G9: =Teams!C10 -> American | H9: vs | I9: =Teams!C11 -> Appalachian State | J9: {=_xlfn.XLOOKUP(I9,Teams[[#All],[Team]],Teams[[#All],[Seed]],0,0,1)} -> 11 | K9: =_xlfn.XLOOKUP(G9,Teams!$C:$C,Teams!$E:$E,,0,1) -> #VALUE! | L9: =RANDBETWEEN(90,120) -> 107 | M9: =_xlfn.XLOOKUP(I9,Teams!$C:$C,Teams!$E:$E,,0,1) -> #VALUE! | N9: =RANDBETWEEN(90,120) -> 104 | O9: =IF(L9>N9,G9,I9) -> American | P9: =_xlfn.XLOOKUP(O9,Teams!$C:$C,Teams!$E:$E,,0,1) -> #VALUE! | R9: =IF( O9=G9, IF(F9>J9,TRUE,FALSE), IF(J9>F9,TRUE,FALSE)) -> FALSE
A10: =G10 -> Arizona | B10: =I10 -> Arizona State | C10: =IF(O10="","",IF(A10=O10,B10,A10)) -> Arizona State | D10: =IF(SeedType=1,0,IF(SeedType=2,VLOOKUP(O10,SeedInfo,2,FALSE)*1,MAX(VLOOKUP(O10,SeedInfo,2,FALSE)-VLOOKUP(C10,SeedInfo,2,FALSE),0))) -> #REF! | E10: 6 | F10: {=_xlfn.XLOOKUP(G10,Teams[[#All],[Team]],Teams[[#All],[Seed]],0,0,1)} -> 3 | G10: =Teams!C12 -> Arizona | H10: vs | I10: =Teams!C13 -> Arizona State | J10: {=_xlfn.XLOOKUP(I10,Teams[[#All],[Team]],Teams[[#All],[Seed]],0,0,1)} -> 14 | K10: =_xlfn.XLOOKUP(G10,Teams!$C:$C,Teams!$E:$E,,0,1) -> #VALUE! | L10: =RANDBETWEEN(90,120) -> 117 | M10: =_xlfn.XLOOKUP(I10,Teams!$C:$C,Teams!$E:$E,,0,1) -> #VALUE! | N10: =RANDBETWEEN(90,120) -> 103 | O10: =IF(L10>N10,G10,I10) -> Arizona | P10: =_xlfn.XLOOKUP(O10,Teams!$C:$C,Teams!$E:$E,,0,1) -> #VALUE! | R10: =IF( O10=G10, IF(F10>J10,TRUE,FALSE), IF(J10>F10,TRUE,FALSE)) -> FALSE
A11: =G11 -> Arkansas | B11: =I11 -> Arkansas State | C11: =IF(O11="","",IF(A11=O11,B11,A11)) -> Arkansas | D11: =IF(SeedType=1,0,IF(SeedType=2,VLOOKUP(O11,SeedInfo,2,FALSE)*1,MAX(VLOOKUP(O11,SeedInfo,2,FALSE)-VLOOKUP(C11,SeedInfo,2,FALSE),0))) -> #REF! | E11: 7 | F11: {=_xlfn.XLOOKUP(G11,Teams[[#All],[Team]],Teams[[#All],[Seed]],0,0,1)} -> 7 | G11: =Teams!C14 -> Arkansas | H11: vs | I11: =Teams!C15 -> Arkansas State | J11: {=_xlfn.XLOOKUP(I11,Teams[[#All],[Team]],Teams[[#All],[Seed]],0,0,1)} -> 10 | K11: =_xlfn.XLOOKUP(G11,Teams!$C:$C,Teams!$E:$E,,0,1) -> #VALUE! | L11: =RANDBETWEEN(90,120) -> 99 | M11: =_xlfn.XLOOKUP(I11,Teams!$C:$C,Teams!$E:$E,,0,1) -> #VALUE! | N11: =RANDBETWEEN(90,120) -> 102 | O11: =IF(L11>N11,G11,I11) -> Arkansas State | P11: =_xlfn.XLOOKUP(O11,Teams!$C:$C,Teams!$E:$E,,0,1) -> #VALUE! | R11: =IF( O11=G11, IF(F11>J11,TRUE,FALSE), IF(J11>F11,TRUE,FALSE)) -> TRUE
A12: =G12 -> Arkansas-Pine Bluff | B12: =I12 -> Army | C12: =IF(O12="","",IF(A12=O12,B12,A12)) -> Arkansas-Pine Bluff | D12: =IF(SeedType=1,0,IF(SeedType=2,VLOOKUP(O12,SeedInfo,2,FALSE)*1,MAX(VLOOKUP(O12,SeedInfo,2,FALSE)-VLOOKUP(C12,SeedInfo,2,FALSE),0))) -> #REF! | E12: 8 | F12: {=_xlfn.XLOOKUP(G12,Teams[[#All],[Team]],Teams[[#All],[Seed]],0,0,1)} -> 2 | G12: =Teams!C16 -> Arkansas-Pine Bluff | H12: vs | I12: =Teams!C17 -> Army | J12: {=_xlfn.XLOOKUP(I12,Teams[[#All],[Team]],Teams[[#All],[Seed]],0,0,1)} -> 15 | K12: =_xlfn.XLOOKUP(G12,Teams!$C:$C,Teams!$E:$E,,0,1) -> #VALUE! | L12: =RANDBETWEEN(90,120) -> 104 | M12: =_xlfn.XLOOKUP(I12,Teams!$C:$C,Teams!$E:$E,,0,1) -> #VALUE! | N12: =RANDBETWEEN(90,120) -> 119 | O12: =IF(L12>N12,G12,I12) -> Army | P12: =_xlfn.XLOOKUP(O12,Teams!$C:$C,Teams!$E:$E,,0,1) -> #VALUE! | R12: =IF( O12=G12, IF(F12>J12,TRUE,FALSE), IF(J12>F12,TRUE,FALSE)) -> TRUE
A13: =G13 -> Auburn | B13: =I13 -> Austin Peay | C13: =IF(O13="","",IF(A13=O13,B13,A13)) -> Austin Peay | D13: =IF(SeedType=1,0,IF(SeedType=2,VLOOKUP(O13,SeedInfo,2,FALSE)*1,MAX(VLOOKUP(O13,SeedInfo,2,FALSE)-VLOOKUP(C13,SeedInfo,2,FALSE),0))) -> #REF! | E13: 9 | F13: {=_xlfn.XLOOKUP(G13,Teams[[#All],[Team]],Teams[[#All],[Seed]],0,0,1)} -> 1 | G13: =Teams!C18 -> Auburn | H13: vs | I13: =Teams!C19 -> Austin Peay | J13: {=_xlfn.XLOOKUP(I13,Teams[[#All],[Team]],Teams[[#All],[Seed]],0,0,1)} -> 16 | K13: =_xlfn.XLOOKUP(G13,Teams!$C:$C,Teams!$E:$E,,0,1) -> #VALUE! | L13: =RANDBETWEEN(90,120) -> 117 | M13: =_xlfn.XLOOKUP(I13,Teams!$C:$C,Teams!$E:$E,,0,1) -> #VALUE! | N13: =RANDBETWEEN(90,120) -> 111 | O13: =IF(L13>N13,G13,I13) -> Auburn | P13: =_xlfn.XLOOKUP(O13,Teams!$C:$C,Teams!$E:$E,,0,1) -> #VALUE! | R13: =IF( O13=G13, IF(F13>J13,TRUE,FALSE), IF(J13>F13,TRUE,FALSE)) -> FALSE
A14: =G14 -> Ball State | B14: =I14 -> Baylor | C14: =IF(O14="","",IF(A14=O14,B14,A14)) -> Ball State | D14: =IF(SeedType=1,0,IF(SeedType=2,VLOOKUP(O14,SeedInfo,2,FALSE)*1,MAX(VLOOKUP(O14,SeedInfo,2,FALSE)-VLOOKUP(C14,SeedInfo,2,FALSE),0))) -> #REF! | E14: 10 | F14: {=_xlfn.XLOOKUP(G14,Teams[[#All],[Team]],Teams[[#All],[Seed]],0,0,1)} -> 8 | G14: =Teams!C20 -> Ball State | H14: vs | I14: =Teams!C21 -> Baylor | J14: {=_xlfn.XLOOKUP(I14,Teams[[#All],[Team]],Teams[[#All],[Seed]],0,0,1)} -> 9 | K14: =_xlfn.XLOOKUP(G14,Teams!$C:$C,Teams!$E:$E,,0,1) -> #VALUE! | L14: =RANDBETWEEN(90,120) -> 105 | M14: =_xlfn.XLOOKUP(I14,Teams!$C:$C,Teams!$E:$E,,0,1) -> #VALUE! | N14: =RANDBETWEEN(90,120) -> 109 | O14: =IF(L14>N14,G14,I14) -> Baylor | P14: =_xlfn.XLOOKUP(O14,Teams!$C:$C,Teams!$E:$E,,0,1) -> #VALUE! | R14: =IF( O14=G14, IF(F14>J14,TRUE,FALSE), IF(J14>F14,TRUE,FALSE)) -> TRUE
A15: =G15 -> Bellarmine | B15: =I15 -> Belmont | C15: =IF(O15="","",IF(A15=O15,B15,A15)) -> Bellarmine | D15: =IF(SeedType=1,0,IF(SeedType=2,VLOOKUP(O15,SeedInfo,2,FALSE)*1,MAX(VLOOKUP(O15,SeedInfo,2,FALSE)-VLOOKUP(C15,SeedInfo,2,FALSE),0))) -> #REF! | E15: 11 | F15: {=_xlfn.XLOOKUP(G15,Teams[[#All],[Team]],Teams[[#All],[Seed]],0,0,1)} -> 5 | G15: =Teams!C22 -> Bellarmine | H15: vs | I15: =Teams!C23 -> Belmont | J15: {=_xlfn.XLOOKUP(I15,Teams[[#All],[Team]],Teams[[#All],[Seed]],0,0,1)} -> 12 | K15: =_xlfn.XLOOKUP(G15,Teams!$C:$C,Teams!$E:$E,,0,1) -> #VALUE! | L15: =RANDBETWEEN(90,120) -> 99 | M15: =_xlfn.XLOOKUP(I15,Teams!$C:$C,Teams!$E:$E,,0,1) -> #VALUE! | N15: =RANDBETWEEN(90,120) -> 111 | O15: =IF(L15>N15,G15,I15) -> Belmont | P15: =_xlfn.XLOOKUP(O15,Teams!$C:$C,Teams!$E:$E,,0,1) -> #VALUE! | R15: =IF( O15=G15, IF(F15>J15,TRUE,FALSE), IF(J15>F15,TRUE,FALSE)) -> TRUE
A16: =G16 -> Bethune-Cookman | B16: =I16 -> Binghamton | C16: =IF(O16="","",IF(A16=O16,B16,A16)) -> Bethune-Cookman | D16: =IF(SeedType=1,0,IF(SeedType=2,VLOOKUP(O16,SeedInfo,2,FALSE)*1,MAX(VLOOKUP(O16,SeedInfo,2,FALSE)-VLOOKUP(C16,SeedInfo,2,FALSE),0))) -> #REF! | E16: 12 | F16: {=_xlfn.XLOOKUP(G16,Teams[[#All],[Team]],Teams[[#All],[Seed]],0,0,1)} -> 4 | G16: =Teams!C24 -> Bethune-Cookman | H16: vs | I16: =Teams!C25 -> Binghamton | J16: {=_xlfn.XLOOKUP(I16,Teams[[#All],[Team]],Teams[[#All],[Seed]],0,0,1)} -> 13 | K16: =_xlfn.XLOOKUP(G16,Teams!$C:$C,Teams!$E:$E,,0,1) -> #VALUE! | L16: =RANDBETWEEN(90,120) -> 99 | M16: =_xlfn.XLOOKUP(I16,Teams!$C:$C,Teams!$E:$E,,0,1) -> #VALUE! | N16: =RANDBETWEEN(90,120) -> 117 | O16: =IF(L16>N16,G16,I16) -> Binghamton | P16: =_xlfn.XLOOKUP(O16,Teams!$C:$C,Teams!$E:$E,,0,1) -> #VALUE! | R16: =IF( O16=G16, IF(F16>J16,TRUE,FALSE), IF(J16>F16,TRUE,FALSE)) -> TRUE
A17: =G17 -> Boise State | B17: =I17 -> Boston College | C17: =IF(O17="","",IF(A17=O17,B17,A17)) -> Boise State | D17: =IF(SeedType=1,0,IF(SeedType=2,VLOOKUP(O17,SeedInfo,2,FALSE)*1,MAX(VLOOKUP(O17,SeedInfo,2,FALSE)-VLOOKUP(C17,SeedInfo,2,FALSE),0))) -> #REF! | E17: 13 | F17: {=_xlfn.XLOOKUP(G17,Teams[[#All],[Team]],Teams[[#All],[Seed]],0,0,1)} -> 6 | G17: =Teams!C26 -> Boise State | H17: vs | I17: =Teams!C27 -> Boston College | J17: {=_xlfn.XLOOKUP(I17,Teams[[#All],[Team]],Teams[[#All],[Seed]],0,0,1)} -> 11 | K17: =_xlfn.XLOOKUP(G17,Teams!$C:$C,Teams!$E:$E,,0,1) -> #VALUE! | L17: =RANDBETWEEN(90,120) -> 103 | M17: =_xlfn.XLOOKUP(I17,Teams!$C:$C,Teams!$E:$E,,0,1) -> #VALUE! | N17: =RANDBETWEEN(90,120) -> 113 | O17: =IF(L17>N17,G17,I17) -> Boston College | P17: =_xlfn.XLOOKUP(O17,Teams!$C:$C,Teams!$E:$E,,0,1) -> #VALUE! | R17: =IF( O17=G17, IF(F17>J17,TRUE,FALSE), IF(J17>F17,TRUE,FALSE)) -> TRUE
A18: =G18 -> Boston University | B18: =I18 -> Bowling Green | C18: =IF(O18="","",IF(A18=O18,B18,A18)) -> Boston University | D18: =IF(SeedType=1,0,IF(SeedType=2,VLOOKUP(O18,SeedInfo,2,FALSE)*1,MAX(VLOOKUP(O18,SeedInfo,2,FALSE)-VLOOKUP(C18,SeedInfo,2,FALSE),0))) -> #REF! | E18: 14 | F18: {=_xlfn.XLOOKUP(G18,Teams[[#All],[Team]],Teams[[#All],[Seed]],0,0,1)} -> 3 | G18: =Teams!C28 -> Boston University | H18: vs | I18: =Teams!C29 -> Bowling Green | J18: {=_xlfn.XLOOKUP(I18,Teams[[#All],[Team]],Teams[[#All],[Seed]],0,0,1)} -> 14 | K18: =_xlfn.XLOOKUP(G18,Teams!$C:$C,Teams!$E:$E,,0,1) -> #VALUE! | L18: =RANDBETWEEN(90,120) -> 99 | M18: =_xlfn.XLOOKUP(I18,Teams!$C:$C,Teams!$E:$E,,0,1) -> #VALUE! | N18: =RANDBETWEEN(90,120) -> 110 | O18: =IF(L18>N18,G18,I18) -> Bowling Green | P18: =_xlfn.XLOOKUP(O18,Teams!$C:$C,Teams!$E:$E,,0,1) -> #VALUE! | R18: =IF( O18=G18, IF(F18>J18,TRUE,FALSE), IF(J18>F18,TRUE,FALSE)) -> TRUE
A19: =G19 -> Bradley | B19: =I19 -> Brigham Young | C19: =IF(O19="","",IF(A19=O19,B19,A19)) -> Bradley | D19: =IF(SeedType=1,0,IF(SeedType=2,VLOOKUP(O19,SeedInfo,2,FALSE)*1,MAX(VLOOKUP(O19,SeedInfo,2,FALSE)-VLOOKUP(C19,SeedInfo,2,FALSE),0))) -> #REF! | E19: 15 | F19: {=_xlfn.XLOOKUP(G19,Teams[[#All],[Team]],Teams[[#All],[Seed]],0,0,1)} -> 7 | G19: =Teams!C30 -> Bradley | H19: vs | I19: =Teams!C31 -> Brigham Young | J19: {=_xlfn.XLOOKUP(I19,Teams[[#All],[Team]],Teams[[#All],[Seed]],0,0,1)} -> 10 | K19: =_xlfn.XLOOKUP(G19,Teams!$C:$C,Teams!$E:$E,,0,1) -> #VALUE! | L19: =RANDBETWEEN(90,120) -> 99 | M19: =_xlfn.XLOOKUP(I19,Teams!$C:$C,Teams!$E:$E,,0,1) -> #VALUE! | N19: =RANDBETWEEN(90,120) -> 111 | O19: =IF(L19>N19,G19,I19) -> Brigham Young | P19: =_xlfn.XLOOKUP(O19,Teams!$C:$C,Teams!$E:$E,,0,1) -> #VALUE! | R19: =IF( O19=G19, IF(F19>J19,TRUE,FALSE), IF(J19>F19,TRUE,FALSE)) -> TRUE
A20: =G20 -> Brown | B20: =I20 -> Bryant | C20: =IF(O20="","",IF(A20=O20,B20,A20)) -> Bryant | D20: =IF(SeedType=1,0,IF(SeedType=2,VLOOKUP(O20,SeedInfo,2,FALSE)*1,MAX(VLOOKUP(O20,SeedInfo,2,FALSE)-VLOOKUP(C20,SeedInfo,2,FALSE),0))) -> #REF! | E20: 16 | F20: {=_xlfn.XLOOKUP(G20,Teams[[#All],[Team]],Teams[[#All],[Seed]],0,0,1)} -> 2 | G20: =Teams!C32 -> Brown | H20: vs | I20: =Teams!C33 -> Bryant | J20: {=_xlfn.XLOOKUP(I20,Teams[[#All],[Team]],Teams[[#All],[Seed]],0,0,1)} -> 15 | K20: =_xlfn.XLOOKUP(G20,Teams!$C:$C,Teams!$E:$E,,0,1) -> #VALUE! | L20: =RANDBETWEEN(90,120) -> 120 | M20: =_xlfn.XLOOKUP(I20,Teams!$C:$C,Teams!$E:$E,,0,1) -> #VALUE! | N20: =RANDBETWEEN(90,120) -> 108 | O20: =IF(L20>N20,G20,I20) -> Brown | P20: =_xlfn.XLOOKUP(O20,Teams!$C:$C,Teams!$E:$E,,0,1) -> #VALUE! | R20: =IF( O20=G20, IF(F20>J20,TRUE,FALSE), IF(J20>F20,TRUE,FALSE)) -> FALSE
A21: =G21 -> Bucknell | B21: =I21 -> Buffalo | C21: =IF(O21="","",IF(A21=O21,B21,A21)) -> Buffalo | D21: =IF(SeedType=1,0,IF(SeedType=2,VLOOKUP(O21,SeedInfo,2,FALSE)*1,MAX(VLOOKUP(O21,SeedInfo,2,FALSE)-VLOOKUP(C21,SeedInfo,2,FALSE),0))) -> #REF! | E21: 17 | F21: {=_xlfn.XLOOKUP(G21,Teams[[#All],[Team]],Teams[[#All],[Seed]],0,0,1)} -> 1 | G21: =Teams!C34 -> Bucknell | H21: vs | I21: =Teams!C35 -> Buffalo | J21: {=_xlfn.XLOOKUP(I21,Teams[[#All],[Team]],Teams[[#All],[Seed]],0,0,1)} -> 16 | K21: =_xlfn.XLOOKUP(G21,Teams!$C:$C,Teams!$E:$E,,0,1) -> #VALUE! | L21: =RANDBETWEEN(90,120) -> 104 | M21: =_xlfn.XLOOKUP(I21,Teams!$C:$C,Teams!$E:$E,,0,1) -> #VALUE! | N21: =RANDBETWEEN(90,120) -> 98 | O21: =IF(L21>N21,G21,I21) -> Bucknell | P21: =_xlfn.XLOOKUP(O21,Teams!$C:$C,Teams!$E:$E,,0,1) -> #VALUE! | R21: =IF( O21=G21, IF(F21>J21,TRUE,FALSE), IF(J21>F21,TRUE,FALSE)) -> FALSE
A22: =G22 -> Butler | B22: =I22 -> Cal Poly | C22: =IF(O22="","",IF(A22=O22,B22,A22)) -> Butler | D22: =IF(SeedType=1,0,IF(SeedType=2,VLOOKUP(O22,SeedInfo,2,FALSE)*1,MAX(VLOOKUP(O22,SeedInfo,2,FALSE)-VLOOKUP(C22,SeedInfo,2,FALSE),0))) -> #REF! | E22: 18 | F22: {=_xlfn.XLOOKUP(G22,Teams[[#All],[Team]],Teams[[#All],[Seed]],0,0,1)} -> 8 | G22: =Teams!C36 -> Butler | H22: vs | I22: =Teams!C37 -> Cal Poly | J22: {=_xlfn.XLOOKUP(I22,Teams[[#All],[Team]],Teams[[#All],[Seed]],0,0,1)} -> 9 | K22: =_xlfn.XLOOKUP(G22,Teams!$C:$C,Teams!$E:$E,,0,1) -> #VALUE! | L22: =RANDBETWEEN(90,120) -> 118 | M22: =_xlfn.XLOOKUP(I22,Teams!$C:$C,Teams!$E:$E,,0,1) -> #VALUE! | N22: =RANDBETWEEN(90,120) -> 118 | O22: =IF(L22>N22,G22,I22) -> Cal Poly | P22: =_xlfn.XLOOKUP(O22,Teams!$C:$C,Teams!$E:$E,,0,1) -> #VALUE! | R22: =IF( O22=G22, IF(F22>J22,TRUE,FALSE), IF(J22>F22,TRUE,FALSE)) -> TRUE
A23: =G23 -> Cal State Bakersfield | B23: =I23 -> Cal State Fullerton | C23: =IF(O23="","",IF(A23=O23,B23,A23)) -> Cal State Bakersfield | D23: =IF(SeedType=1,0,IF(SeedType=2,VLOOKUP(O23,SeedInfo,2,FALSE)*1,MAX(VLOOKUP(O23,SeedInfo,2,FALSE)-VLOOKUP(C23,SeedInfo,2,FALSE),0))) -> #REF! | E23: 19 | F23: {=_xlfn.XLOOKUP(G23,Teams[[#All],[Team]],Teams[[#All],[Seed]],0,0,1)} -> 5 | G23: =Teams!C38 -> Cal State Bakersfield | H23: vs | I23: =Teams!C39 -> Cal State Fullerton | J23: {=_xlfn.XLOOKUP(I23,Teams[[#All],[Team]],Teams[[#All],[Seed]],0,0,1)} -> 12 | K23: =_xlfn.XLOOKUP(G23,Teams!$C:$C,Teams!$E:$E,,0,1) -> #VALUE! | L23: =RANDBETWEEN(90,120) -> 98 | M23: =_xlfn.XLOOKUP(I23,Teams!$C:$C,Teams!$E:$E,,0,1) -> #VALUE! | N23: =RANDBETWEEN(90,120) -> 98 | O23: =IF(L23>N23,G23,I23) -> Cal State Fullerton | P23: =_xlfn.XLOOKUP(O23,Teams!$C:$C,Teams!$E:$E,,0,1) -> #VALUE! | R23: =IF( O23=G23, IF(F23>J23,TRUE,FALSE), IF(J23>F23,TRUE,FALSE)) -> TRUE
A24: =G24 -> Cal State Northridge | B24: =I24 -> California | C24: =IF(O24="","",IF(A24=O24,B24,A24)) -> California | D24: =IF(SeedType=1,0,IF(SeedType=2,VLOOKUP(O24,SeedInfo,2,FALSE)*1,MAX(VLOOKUP(O24,SeedInfo,2,FALSE)-VLOOKUP(C24,SeedInfo,2,FALSE),0))) -> #REF! | E24: 20 | F24: {=_xlfn.XLOOKUP(G24,Teams[[#All],[Team]],Teams[[#All],[Seed]],0,0,1)} -> 4 | G24: =Teams!C40 -> Cal State Northridge | H24: vs | I24: =Teams!C41 -> California | J24: {=_xlfn.XLOOKUP(I24,Teams[[#All],[Team]],Teams[[#All],[Seed]],0,0,1)} -> 13 | K24: =_xlfn.XLOOKUP(G24,Teams!$C:$C,Teams!$E:$E,,0,1) -> #VALUE! | L24: =RANDBETWEEN(90,120) -> 110 | M24: =_xlfn.XLOOKUP(I24,Teams!$C:$C,Teams!$E:$E,,0,1) -> #VALUE! | N24: =RANDBETWEEN(90,120) -> 108 | O24: =IF(L24>N24,G24,I24) -> Cal State Northridge | P24: =_xlfn.XLOOKUP(O24,Teams!$C:$C,Teams!$E:$E,,0,1) -> #VALUE! | R24: =IF( O24=G24, IF(F24>J24,TRUE,FALSE), IF(J24>F24,TRUE,FALSE)) -> FALSE
A25: =G25 -> California Baptist | B25: =I25 -> Campbell | C25: =IF(O25="","",IF(A25=O25,B25,A25)) -> California Baptist | D25: =IF(SeedType=1,0,IF(SeedType=2,VLOOKUP(O25,SeedInfo,2,FALSE)*1,MAX(VLOOKUP(O25,SeedInfo,2,FALSE)-VLOOKUP(C25,SeedInfo,2,FALSE),0))) -> #REF! | E25: 21 | F25: {=_xlfn.XLOOKUP(G25,Teams[[#All],[Team]],Teams[[#All],[Seed]],0,0,1)} -> 6 | G25: =Teams!C42 -> California Baptist | H25: vs | I25: =Teams!C43 -> Campbell | J25: {=_xlfn.XLOOKUP(I25,Teams[[#All],[Team]],Teams[[#All],[Seed]],0,0,1)} -> 11 | K25: =_xlfn.XLOOKUP(G25,Teams!$C:$C,Teams!$E:$E,,0,1) -> #VALUE! | L25: =RANDBETWEEN(90,120) -> 104 | M25: =_xlfn.XLOOKUP(I25,Teams!$C:$C,Teams!$E:$E,,0,1) -> #VALUE! | N25: =RANDBETWEEN(90,120) -> 109 | O25: =IF(L25>N25,G25,I25) -> Campbell | P25: =_xlfn.XLOOKUP(O25,Teams!$C:$C,Teams!$E:$E,,0,1) -> #VALUE! | R25: =IF( O25=G25, IF(F25>J25,TRUE,FALSE), IF(J25>F25,TRUE,FALSE)) -> TRUE
A26: =G26 -> Canisius | B26: =I26 -> Central Arkansas | C26: =IF(O26="","",IF(A26=O26,B26,A26)) -> Canisius | D26: =IF(SeedType=1,0,IF(SeedType=2,VLOOKUP(O26,SeedInfo,2,FALSE)*1,MAX(VLOOKUP(O26,SeedInfo,2,FALSE)-VLOOKUP(C26,SeedInfo,2,FALSE),0))) -> #REF! | E26: 22 | F26: {=_xlfn.XLOOKUP(G26,Teams[[#All],[Team]],Teams[[#All],[Seed]],0,0,1)} -> 3 | G26: =Teams!C44 -> Canisius | H26: vs | I26: =Teams!C45 -> Central Arkansas | J26: {=_xlfn.XLOOKUP(I26,Teams[[#All],[Team]],Teams[[#All],[Seed]],0,0,1)} -> 14 | K26: =_xlfn.XLOOKUP(G26,Teams!$C:$C,Teams!$E:$E,,0,1) -> #VALUE! | L26: =RANDBETWEEN(90,120) -> 92 | M26: =_xlfn.XLOOKUP(I26,Teams!$C:$C,Teams!$E:$E,,0,1) -> #VALUE! | N26: =RANDBETWEEN(90,120) -> 98 | O26: =IF(L26>N26,G26,I26) -> Central Arkansas | P26: =_xlfn.XLOOKUP(O26,Teams!$C:$C,Teams!$E:$E,,0,1) -> #VALUE! | R26: =IF( O26=G26, IF(F26>J26,TRUE,FALSE), IF(J26>F26,TRUE,FALSE)) -> TRUE
A27: =G27 -> Central Connecticut State | B27: =I27 -> Central Michigan | C27: =IF(O27="","",IF(A27=O27,B27,A27)) -> Central Connecticut State | D27: =IF(SeedType=1,0,IF(SeedType=2,VLOOKUP(O27,SeedInfo,2,FALSE)*1,MAX(VLOOKUP(O27,SeedInfo,2,FALSE)-VLOOKUP(C27,SeedInfo,2,FALSE),0))) -> #REF! | E27: 23 | F27: {=_xlfn.XLOOKUP(G27,Teams[[#All],[Team]],Teams[[#All],[Seed]],0,0,1)} -> 7 | G27: =Teams!C46 -> Central Connecticut State | H27: vs | I27: =Teams!C47 -> Central Michigan | J27: {=_xlfn.XLOOKUP(I27,Teams[[#All],[Team]],Teams[[#All],[Seed]],0,0,1)} -> 10 | K27: =_xlfn.XLOOKUP(G27,Teams!$C:$C,Teams!$E:$E,,0,1) -> #VALUE! | L27: =RANDBETWEEN(90,120) -> 93 | M27: =_xlfn.XLOOKUP(I27,Teams!$C:$C,Teams!$E:$E,,0,1) -> #VALUE! | N27: =RANDBETWEEN(90,120) -> 94 | O27: =IF(L27>N27,G27,I27) -> Central Michigan | P27: =_xlfn.XLOOKUP(O27,Teams!$C:$C,Teams!$E:$E,,0,1) -> #VALUE! | R27: =IF( O27=G27, IF(F27>J27,TRUE,FALSE), IF(J27>F27,TRUE,FALSE)) -> TRUE
A28: =G28 -> Charleston Southern | B28: =I28 -> Charlotte | C28: =IF(O28="","",IF(A28=O28,B28,A28)) -> Charleston Southern | D28: =IF(SeedType=1,0,IF(SeedType=2,VLOOKUP(O28,SeedInfo,2,FALSE)*1,MAX(VLOOKUP(O28,SeedInfo,2,FALSE)-VLOOKUP(C28,SeedInfo,2,FALSE),0))) -> #REF! | E28: 24 | F28: {=_xlfn.XLOOKUP(G28,Teams[[#All],[Team]],Teams[[#All],[Seed]],0,0,1)} -> 2 | G28: =Teams!C48 -> Charleston Southern | H28: vs | I28: =Teams!C49 -> Charlotte | J28: {=_xlfn.XLOOKUP(I28,Teams[[#All],[Team]],Teams[[#All],[Seed]],0,0,1)} -> 15 | K28: =_xlfn.XLOOKUP(G28,Teams!$C:$C,Teams!$E:$E,,0,1) -> #VALUE! | L28: =RANDBETWEEN(90,120) -> 107 | M28: =_xlfn.XLOOKUP(I28,Teams!$C:$C,Teams!$E:$E,,0,1) -> #VALUE! | N28: =RANDBETWEEN(90,120) -> 120 | O28: =IF(L28>N28,G28,I28) -> Charlotte | P28: =_xlfn.XLOOKUP(O28,Teams!$C:$C,Teams!$E:$E,,0,1) -> #VALUE! | R28: =IF( O28=G28, IF(F28>J28,TRUE,FALSE), IF(J28>F28,TRUE,FALSE)) -> TRUE
A29: =G29 -> Chattanooga | B29: =I29 -> Chicago State | C29: =IF(O29="","",IF(A29=O29,B29,A29)) -> Chicago State | D29: =IF(SeedType=1,0,IF(SeedType=2,VLOOKUP(O29,SeedInfo,2,FALSE)*1,MAX(VLOOKUP(O29,SeedInfo,2,FALSE)-VLOOKUP(C29,SeedInfo,2,FALSE),0))) -> #REF! | E29: 25 | F29: {=_xlfn.XLOOKUP(G29,Teams[[#All],[Team]],Teams[[#All],[Seed]],0,0,1)} -> 1 | G29: =Teams!C50 -> Chattanooga | H29: vs | I29: =Teams!C51 -> Chicago State | J29: {=_xlfn.XLOOKUP(I29,Teams[[#All],[Team]],Teams[[#All],[Seed]],0,0,1)} -> 16 | K29: =_xlfn.XLOOKUP(G29,Teams!$C:$C,Teams!$E:$E,,0,1) -> #VALUE! | L29: =RANDBETWEEN(90,120) -> 112 | M29: =_xlfn.XLOOKUP(I29,Teams!$C:$C,Teams!$E:$E,,0,1) -> #VALUE! | N29: =RANDBETWEEN(90,120) -> 104 | O29: =IF(L29>N29,G29,I29) -> Chattanooga | P29: =_xlfn.XLOOKUP(O29,Teams!$C:$C,Teams!$E:$E,,0,1) -> #VALUE! | R29: =IF( O29=G29, IF(F29>J29,TRUE,FALSE), IF(J29>F29,TRUE,FALSE)) -> FALSE
A30: =G30 -> Cincinnati | B30: =I30 -> Clemson | C30: =IF(O30="","",IF(A30=O30,B30,A30)) -> Cincinnati | D30: =IF(SeedType=1,0,IF(SeedType=2,VLOOKUP(O30,SeedInfo,2,FALSE)*1,MAX(VLOOKUP(O30,SeedInfo,2,FALSE)-VLOOKUP(C30,SeedInfo,2,FALSE),0))) -> #REF! | E30: 26 | F30: {=_xlfn.XLOOKUP(G30,Teams[[#All],[Team]],Teams[[#All],[Seed]],0,0,1)} -> 8 | G30: =Teams!C52 -> Cincinnati | H30: vs | I30: =Teams!C53 -> Clemson | J30: {=_xlfn.XLOOKUP(I30,Teams[[#All],[Team]],Teams[[#All],[Seed]],0,0,1)} -> 9 | K30: =_xlfn.XLOOKUP(G30,Teams!$C:$C,Teams!$E:$E,,0,1) -> #VALUE! | L30: =RANDBETWEEN(90,120) -> 91 | M30: =_xlfn.XLOOKUP(I30,Teams!$C:$C,Teams!$E:$E,,0,1) -> #VALUE! | N30: =RANDBETWEEN(90,120) -> 112 | O30: =IF(L30>N30,G30,I30) -> Clemson | P30: =_xlfn.XLOOKUP(O30,Teams!$C:$C,Teams!$E:$E,,0,1) -> #VALUE! | R30: =IF( O30=G30, IF(F30>J30,TRUE,FALSE), IF(J30>F30,TRUE,FALSE)) -> TRUE
A31: =G31 -> Cleveland State | B31: =I31 -> Coastal Carolina | C31: =IF(O31="","",IF(A31=O31,B31,A31)) -> Coastal Carolina | D31: =IF(SeedType=1,0,IF(SeedType=2,VLOOKUP(O31,SeedInfo,2,FALSE)*1,MAX(VLOOKUP(O31,SeedInfo,2,FALSE)-VLOOKUP(C31,SeedInfo,2,FALSE),0))) -> #REF! | E31: 27 | F31: {=_xlfn.XLOOKUP(G31,Teams[[#All],[Team]],Teams[[#All],[Seed]],0,0,1)} -> 5 | G31: =Teams!C54 -> Cleveland State | H31: vs | I31: =Teams!C55 -> Coastal Carolina | J31: {=_xlfn.XLOOKUP(I31,Teams[[#All],[Team]],Teams[[#All],[Seed]],0,0,1)} -> 12 | K31: =_xlfn.XLOOKUP(G31,Teams!$C:$C,Teams!$E:$E,,0,1) -> #VALUE! | L31: =RANDBETWEEN(90,120) -> 108 | M31: =_xlfn.XLOOKUP(I31,Teams!$C:$C,Teams!$E:$E,,0,1) -> #VALUE! | N31: =RANDBETWEEN(90,120) -> 107 | O31: =IF(L31>N31,G31,I31) -> Cleveland State | P31: =_xlfn.XLOOKUP(O31,Teams!$C:$C,Teams!$E:$E,,0,1) -> #VALUE! | R31: =IF( O31=G31, IF(F31>J31,TRUE,FALSE), IF(J31>F31,TRUE,FALSE)) -> FALSE
A32: =G32 -> Colgate | B32: =I32 -> College of Charleston | C32: =IF(O32="","",IF(A32=O32,B32,A32)) -> Colgate | D32: =IF(SeedType=1,0,IF(SeedType=2,VLOOKUP(O32,SeedInfo,2,FALSE)*1,MAX(VLOOKUP(O32,SeedInfo,2,FALSE)-VLOOKUP(C32,SeedInfo,2,FALSE),0))) -> #REF! | E32: 28 | F32: {=_xlfn.XLOOKUP(G32,Teams[[#All],[Team]],Teams[[#All],[Seed]],0,0,1)} -> 4 | G32: =Teams!C56 -> Colgate | H32: vs | I32: =Teams!C57 -> College of Charleston | J32: {=_xlfn.XLOOKUP(I32,Teams[[#All],[Team]],Teams[[#All],[Seed]],0,0,1)} -> 13 | K32: =_xlfn.XLOOKUP(G32,Teams!$C:$C,Teams!$E:$E,,0,1) -> #VALUE! | L32: =RANDBETWEEN(90,120) -> 98 | M32: =_xlfn.XLOOKUP(I32,Teams!$C:$C,Teams!$E:$E,,0,1) -> #VALUE! | N32: =RANDBETWEEN(90,120) -> 118 | O32: =IF(L32>N32,G32,I32) -> College of Charleston | P32: =_xlfn.XLOOKUP(O32,Teams!$C:$C,Teams!$E:$E,,0,1) -> #VALUE! | R32: =IF( O32=G32, IF(F32>J32,TRUE,FALSE), IF(J32>F32,TRUE,FALSE)) -> TRUE
A33: =G33 -> Colorado | B33: =I33 -> Colorado State | C33: =IF(O33="","",IF(A33=O33,B33,A33)) -> Colorado State | D33: =IF(SeedType=1,0,IF(SeedType=2,VLOOKUP(O33,SeedInfo,2,FALSE)*1,MAX(VLOOKUP(O33,SeedInfo,2,FALSE)-VLOOKUP(C33,SeedInfo,2,FALSE),0))) -> #REF! | E33: 29 | F33: {=_xlfn.XLOOKUP(G33,Teams[[#All],[Team]],Teams[[#All],[Seed]],0,0,1)} -> 6 | G33: =Teams!C58 -> Colorado | H33: vs | I33: =Teams!C59 -> Colorado State | J33: {=_xlfn.XLOOKUP(I33,Teams[[#All],[Team]],Teams[[#All],[Seed]],0,0,1)} -> 11 | K33: =_xlfn.XLOOKUP(G33,Teams!$C:$C,Teams!$E:$E,,0,1) -> #VALUE! | L33: =RANDBETWEEN(90,120) -> 101 | M33: =_xlfn.XLOOKUP(I33,Teams!$C:$C,Teams!$E:$E,,0,1) -> #VALUE! | N33: =RANDBETWEEN(90,120) -> 91 | O33: =IF(L33>N33,G33,I33) -> Colorado | P33: =_xlfn.XLOOKUP(O33,Teams!$C:$C,Teams!$E:$E,,0,1) -> #VALUE! | R33: =IF( O33=G33, IF(F33>J33,TRUE,FALSE), IF(J33>F33,TRUE,FALSE)) -> FALSE
A34: =G34 -> Columbia | B34: =I34 -> Connecticut | C34: =IF(O34="","",IF(A34=O34,B34,A34)) -> Columbia | D34: =IF(SeedType=1,0,IF(SeedType=2,VLOOKUP(O34,SeedInfo,2,FALSE)*1,MAX(VLOOKUP(O34,SeedInfo,2,FALSE)-VLOOKUP(C34,SeedInfo,2,FALSE),0))) -> #REF! | E34: 30 | F34: {=_xlfn.XLOOKUP(G34,Teams[[#All],[Team]],Teams[[#All],[Seed]],0,0,1)} -> 3 | G34: =Teams!C60 -> Columbia | H34: vs | I34: =Teams!C61 -> Connecticut | J34: {=_xlfn.XLOOKUP(I34,Teams[[#All],[Team]],Teams[[#All],[Seed]],0,0,1)} -> 14 | K34: =_xlfn.XLOOKUP(G34,Teams!$C:$C,Teams!$E:$E,,0,1) -> #VALUE! | L34: =RANDBETWEEN(90,120) -> 99 | M34: =_xlfn.XLOOKUP(I34,Teams!$C:$C,Teams!$E:$E,,0,1) -> #VALUE! | N34: =RANDBETWEEN(90,120) -> 102 | O34: =IF(L34>N34,G34,I34) -> Connecticut | P34: =_xlfn.XLOOKUP(O34,Teams!$C:$C,Teams!$E:$E,,0,1) -> #VALUE! | R34: =IF( O34=G34, IF(F34>J34,TRUE,FALSE), IF(J34>F34,TRUE,FALSE)) -> TRUE
A35: =G35 -> Coppin State | B35: =I35 -> Cornell | C35: =IF(O35="","",IF(A35=O35,B35,A35)) -> Cornell | D35: =IF(SeedType=1,0,IF(SeedType=2,VLOOKUP(O35,SeedInfo,2,FALSE)*1,MAX(VLOOKUP(O35,SeedInfo,2,FALSE)-VLOOKUP(C35,SeedInfo,2,FALSE),0))) -> #REF! | E35: 31 | F35: {=_xlfn.XLOOKUP(G35,Teams[[#All],[Team]],Teams[[#All],[Seed]],0,0,1)} -> 7 | G35: =Teams!C62 -> Coppin State | H35: vs | I35: =Teams!C63 -> Cornell | J35: {=_xlfn.XLOOKUP(I35,Teams[[#All],[Team]],Teams[[#All],[Seed]],0,0,1)} -> 10 | K35: =_xlfn.XLOOKUP(G35,Teams!$C:$C,Teams!$E:$E,,0,1) -> #VALUE! | L35: =RANDBETWEEN(90,120) -> 113 | M35: =_xlfn.XLOOKUP(I35,Teams!$C:$C,Teams!$E:$E,,0,1) -> #VALUE! | N35: =RANDBETWEEN(90,120) -> 99 | O35: =IF(L35>N35,G35,I35) -> Coppin State | P35: =_xlfn.XLOOKUP(O35,Teams!$C:$C,Teams!$E:$E,,0,1) -> #VALUE! | R35: =IF( O35=G35, IF(F35>J35,TRUE,FALSE), IF(J35>F35,TRUE,FALSE)) -> FALSE
A36: =G36 -> Creighton | B36: =I36 -> Dartmouth | C36: =IF(O36="","",IF(A36=O36,B36,A36)) -> Creighton | D36: =IF(SeedType=1,0,IF(SeedType=2,VLOOKUP(O36,SeedInfo,2,FALSE)*1,MAX(VLOOKUP(O36,SeedInfo,2,FALSE)-VLOOKUP(C36,SeedInfo,2,FALSE),0))) -> #REF! | E36: 32 | F36: {=_xlfn.XLOOKUP(G36,Teams[[#All],[Team]],Teams[[#All],[Seed]],0,0,1)} -> 2 | G36: =Teams!C64 -> Creighton | H36: vs | I36: =Teams!C65 -> Dartmouth | J36: {=_xlfn.XLOOKUP(I36,Teams[[#All],[Team]],Teams[[#All],[Seed]],0,0,1)} -> 15 | K36: =_xlfn.XLOOKUP(G36,Teams!$C:$C,Teams!$E:$E,,0,1) -> #VALUE! | L36: =RANDBETWEEN(90,120) -> 103 | M36: =_xlfn.XLOOKUP(I36,Teams!$C:$C,Teams!$E:$E,,0,1) -> #VALUE! | N36: =RANDBETWEEN(90,120) -> 103 | O36: =IF(L36>N36,G36,I36) -> Dartmouth | P36: =_xlfn.XLOOKUP(O36,Teams!$C:$C,Teams!$E:$E,,0,1) -> #VALUE! | R36: =IF( O36=G36, IF(F36>J36,TRUE,FALSE), IF(J36>F36,TRUE,FALSE)) -> TRUE
E37: Game # | F37: =Bracket!F2 -> Second Round | O37: Winner
A38: =G38 -> Air Force | B38: =I38 -> Alabama | C38: =IF(O38="","",IF(A38=O38,B38,A38)) -> Air Force | D38: =IF(SeedType=1,0,IF(SeedType=2,VLOOKUP(O38,SeedInfo,2,FALSE)*2,MAX(VLOOKUP(O38,SeedInfo,2,FALSE)-VLOOKUP(C38,SeedInfo,2,FALSE),0))) -> #REF! | E38: =Bracket!F7 -> 33 | F38: {=_xlfn.XLOOKUP(G38,Teams[[#All],[Team]],Teams[[#All],[Seed]],0,0,1)} -> 16 | G38: =O5 -> Air Force | H38: vs | I38: =O6 -> Alabama | J38: {=_xlfn.XLOOKUP(I38,Teams[[#All],[Team]],Teams[[#All],[Seed]],0,0,1)} -> 9 | K38: =_xlfn.XLOOKUP(G38,Teams!$C:$C,Teams!$E:$E,,0,1) -> #VALUE! | L38: =RANDBETWEEN(90,120) -> 92 | M38: =_xlfn.XLOOKUP(I38,Teams!$C:$C,Teams!$E:$E,,0,1) -> #VALUE! | N38: =RANDBETWEEN(90,120) -> 108 | O38: =IF(L38>N38,G38,I38) -> Alabama | P38: =_xlfn.XLOOKUP(O38,Teams!$C:$C,Teams!$E:$E,,0,1) -> #VALUE! | R38: =IF( O38=G38, IF(F38>J38,TRUE,FALSE), IF(J38>F38,TRUE,FALSE)) -> FALSE
A39: =G39 -> Alabama A&M | B39: =I39 -> Alcorn State | C39: =IF(O39="","",IF(A39=O39,B39,A39)) -> Alabama A&M | D39: =IF(SeedType=1,0,IF(SeedType=2,VLOOKUP(O39,SeedInfo,2,FALSE)*2,MAX(VLOOKUP(O39,SeedInfo,2,FALSE)-VLOOKUP(C39,SeedInfo,2,FALSE),0))) -> #REF! | E39: 34 | F39: {=_xlfn.XLOOKUP(G39,Teams[[#All],[Team]],Teams[[#All],[Seed]],0,0,1)} -> 5 | G39: =O7 -> Alabama A&M | H39: vs | I39: =O8 -> Alcorn State | J39: {=_xlfn.XLOOKUP(I39,Teams[[#All],[Team]],Teams[[#All],[Seed]],0,0,1)} -> 13 | K39: =_xlfn.XLOOKUP(G39,Teams!$C:$C,Teams!$E:$E,,0,1) -> #VALUE! | L39: =RANDBETWEEN(90,120) -> 100 | M39: =_xlfn.XLOOKUP(I39,Teams!$C:$C,Teams!$E:$E,,0,1) -> #VALUE! | N39: =RANDBETWEEN(90,120) -> 112 | O39: =IF(L39>N39,G39,I39) -> Alcorn State | P39: =_xlfn.XLOOKUP(O39,Teams!$C:$C,Teams!$E:$E,,0,1) -> #VALUE! | R39: =IF( O39=G39, IF(F39>J39,TRUE,FALSE), IF(J39>F39,TRUE,FALSE)) -> TRUE
A40: =G40 -> American | B40: =I40 -> Arizona | C40: =IF(O40="","",IF(A40=O40,B40,A40)) -> Arizona | D40: =IF(SeedType=1,0,IF(SeedType=2,VLOOKUP(O40,SeedInfo,2,FALSE)*2,MAX(VLOOKUP(O40,SeedInfo,2,FALSE)-VLOOKUP(C40,SeedInfo,2,FALSE),0))) -> #REF! | E40: 35 | F40: {=_xlfn.XLOOKUP(G40,Teams[[#All],[Team]],Teams[[#All],[Seed]],0,0,1)} -> 6 | G40: =O9 -> American | H40: vs | I40: =O10 -> Arizona | J40: {=_xlfn.XLOOKUP(I40,Teams[[#All],[Team]],Teams[[#All],[Seed]],0,0,1)} -> 3 | K40: =_xlfn.XLOOKUP(G40,Teams!$C:$C,Teams!$E:$E,,0,1) -> #VALUE! | L40: =RANDBETWEEN(90,120) -> 103 | M40: =_xlfn.XLOOKUP(I40,Teams!$C:$C,Teams!$E:$E,,0,1) -> #VALUE! | N40: =RANDBETWEEN(90,120) -> 97 | O40: =IF(L40>N40,G40,I40) -> American | P40: =_xlfn.XLOOKUP(O40,Teams!$C:$C,Teams!$E:$E,,0,1) -> #VALUE! | R40: =IF( O40=G40, IF(F40>J40,TRUE,FALSE), IF(J40>F40,TRUE,FALSE)) -> TRUE
A41: =G41 -> Arkansas State | B41: =I41 -> Army | C41: =IF(O41="","",IF(A41=O41,B41,A41)) -> Army | D41: =IF(SeedType=1,0,IF(SeedType=2,VLOOKUP(O41,SeedInfo,2,FALSE)*2,MAX(VLOOKUP(O41,SeedInfo,2,FALSE)-VLOOKUP(C41,SeedInfo,2,FALSE),0))) -> #REF! | E41: 36 | F41: {=_xlfn.XLOOKUP(G41,Teams[[#All],[Team]],Teams[[#All],[Seed]],0,0,1)} -> 10 | G41: =O11 -> Arkansas State | H41: vs | I41: =O12 -> Army | J41: {=_xlfn.XLOOKUP(I41,Teams[[#All],[Team]],Teams[[#All],[Seed]],0,0,1)} -> 15 | K41: =_xlfn.XLOOKUP(G41,Teams!$C:$C,Teams!$E:$E,,0,1) -> #VALUE! | L41: =RANDBETWEEN(90,120) -> 117 | M41: =_xlfn.XLOOKUP(I41,Teams!$C:$C,Teams!$E:$E,,0,1) -> #VALUE! | N41: =RANDBETWEEN(90,120) -> 112 | O41: =IF(L41>N41,G41,I41) -> Arkansas State | P41: =_xlfn.XLOOKUP(O41,Teams!$C:$C,Teams!$E:$E,,0,1) -> #VALUE! | R41: =IF( O41=G41, IF(F41>J41,TRUE,FALSE), IF(J41>F41,TRUE,FALSE)) -> FALSE
A42: =G42 -> Auburn | B42: =I42 -> Baylor | C42: =IF(O42="","",IF(A42=O42,B42,A42)) -> Baylor | D42: =IF(SeedType=1,0,IF(SeedType=2,VLOOKUP(O42,SeedInfo,2,FALSE)*2,MAX(VLOOKUP(O42,SeedInfo,2,FALSE)-VLOOKUP(C42,SeedInfo,2,FALSE),0))) -> #REF! | E42: 37 | F42: {=_xlfn.XLOOKUP(G42,Teams[[#All],[Team]],Teams[[#All],[Seed]],0,0,1)} -> 1 | G42: =O13 -> Auburn | H42: vs | I42: =O14 -> Baylor | J42: {=_xlfn.XLOOKUP(I42,Teams[[#All],[Team]],Teams[[#All],[Seed]],0,0,1)} -> 9 | K42: =_xlfn.XLOOKUP(G42,Teams!$C:$C,Teams!$E:$E,,0,1) -> #VALUE! | L42: =RANDBETWEEN(90,120) -> 106 | M42: =_xlfn.XLOOKUP(I42,Teams!$C:$C,Teams!$E:$E,,0,1) -> #VALUE! | N42: =RANDBETWEEN(90,120) -> 90 | O42: =IF(L42>N42,G42,I42) -> Auburn | P42: =_xlfn.XLOOKUP(O42,Teams!$C:$C,Teams!$E:$E,,0,1) -> #VALUE! | R42: =IF( O42=G42, IF(F42>J42,TRUE,FALSE), IF(J42>F42,TRUE,FALSE)) -> FALSE
...

Sheet Bracket
B1: 2026 NCAA Basketball Tournament Bracket
C2: First Round | F2: Second Round | I2: Sweet 16 | L2: Elite 8 | O2: Final Four | S2: Championship | AA2: Final Four | AD2: Elite 8 | AG2: Sweet 16 | AJ2: =F2 -> Second Round | AM2: =C2 -> First Round | AU2: checkbox
AU3: x
B5: 1 | C5: =Games!G5 -> Abilene Christian | D5: =_xlfn.XLOOKUP(C5,Teams!$C:$C,Teams!$E:$E,,0,1) -> #VALUE! | E5: =Games!L5 -> 104 | F5: =Games!O5 -> Air Force | G5: =_xlfn.XLOOKUP(F5,Teams!$C:$C,Teams!$E:$E,,0,1) -> #VALUE! | H5: =Games!L38 -> 92 | AH5: =Games!L46 -> 116 | AI5: =_xlfn.XLOOKUP(AJ5,Teams!$C:$C,Teams!$E:$E,,0,1) -> #VALUE! | AJ5: =Games!O21 -> Bucknell | AK5: =Games!L21 -> 104 | AL5: =_xlfn.XLOOKUP(AM5,Teams!$C:$C,Teams!$E:$E,,0,1) -> #VALUE! | AM5: =Games!G21 -> Bucknell | AN5: 1 | AU5: =IF(AP29="x",TRUE,FALSE) -> TRUE
A6: =IF($AU$5=TRUE,1,"") -> 1 | AO6: =IF($AU$5=TRUE,A66+1,"") -> 17
B7: 16 | C7: =Games!I5 -> Air Force | D7: =_xlfn.XLOOKUP(C7,Teams!$C:$C,Teams!$E:$E,,0,1) -> #VALUE! | E7: =Games!N5 -> 111 | F7: =IF($AU$5=TRUE,AO66+1,"") -> 33 | I7: =Games!O38 -> Alabama | J7: =_xlfn.XLOOKUP(I7,Teams!$C:$C,Teams!$E:$E,,0,1) -> #VALUE! | K7: =Games!L55 -> 99 | AE7: =Games!L59 -> 115 | AF7: =_xlfn.XLOOKUP(AG7,Teams!$C:$C,Teams!$E:$E,,0,1) -> #VALUE! | AG7: =Games!O46 -> Cal Poly | AJ7: =IF($AU$5=TRUE,F63+1,"") -> 41 | AK7: =Games!N21 -> 98 | AL7: =_xlfn.XLOOKUP(AM7,Teams!$C:$C,Teams!$E:$E,,0,1) -> #VALUE! | AM7: =Games!I21 -> Buffalo | AN7: 16
B9: 8 | C9: =Games!G6 -> Akron | D9: =_xlfn.XLOOKUP(C9,Teams!$C:$C,Teams!$E:$E,,0,1) -> #VALUE! | E9: =Games!L6 -> 111 | F9: =Games!O6 -> Alabama | G9: =_xlfn.XLOOKUP(F9,Teams!$C:$C,Teams!$E:$E,,0,1) -> #VALUE! | H9: =Games!N38 -> 108 | AH9: =Games!N46 -> 118 | AI9: =_xlfn.XLOOKUP(AJ9,Teams!$C:$C,Teams!$E:$E,,0,1) -> #VALUE! | AJ9: =Games!O22 -> Cal Poly | AK9: =Games!L22 -> 118 | AL9: =_xlfn.XLOOKUP(AM9,Teams!$C:$C,Teams!$E:$E,,0,1) -> #VALUE! | AM9: =Games!G22 -> Butler | AN9: 8
A10: =IF($AU$5=TRUE,A6+1,"") -> 2 | AO10: =IF($AU$5=TRUE,AO6+1,"") -> 18
B11: 9 | C11: =Games!I6 -> Alabama | D11: =_xlfn.XLOOKUP(C11,Teams!$C:$C,Teams!$E:$E,,0,1) -> #VALUE! | E11: =Games!N6 -> 120 | I11: =IF($AU$5=TRUE,AJ63+1,"") -> 49 | L11: =Games!O55 -> Alcorn State | M11: =_xlfn.XLOOKUP(L11,Teams!$C:$C,Teams!$E:$E,,0,1) -> #VALUE! | N11: =Games!L64 -> 93 | T11: =_xlfn.XLOOKUP(S32,Teams!$C:$C,Teams!$E:$E,,0,1) -> #VALUE! | AB11: =Games!L66 -> 118 | AC11: =_xlfn.XLOOKUP(AD11,Teams!$C:$C,Teams!$E:$E,,0,1) -> #VALUE! | AD11: =Games!O59 -> Cal Poly | AG11: =IF($AU$5=TRUE,I59+1,"") -> 53 | AK11: =Games!N22 -> 118 | AL11: =_xlfn.XLOOKUP(AM11,Teams!$C:$C,Teams!$E:$E,,0,1) -> #VALUE! | AM11: =Games!I22 -> Cal Poly | AN11: 9
B13: 5 | C13: =Games!G7 -> Alabama A&M | D13: =_xlfn.XLOOKUP(C13,Teams!$C:$C,Teams!$E:$E,,0,1) -> #VALUE! | E13: =Games!L7 -> 100 | F13: =Games!O7 -> Alabama A&M | G13: =_xlfn.XLOOKUP(F13,Teams!$C:$C,Teams!$E:$E,,0,1) -> #VALUE! | H13: =Games!L39 -> 100 | AH13: =Games!L47 -> 106 | AI13: =_xlfn.XLOOKUP(AJ13,Teams!$C:$C,Teams!$E:$E,,0,1) -> #VALUE! | AJ13: =Games!O23 -> Cal State Fullerton | AK13: =Games!L23 -> 98 | AL13: =_xlfn.XLOOKUP(AM13,Teams!$C:$C,Teams!$E:$E,,0,1) -> #VALUE! | AM13: =Games!G23 -> Cal State Bakersfield | AN13: 5
A14: =IF($AU$5=TRUE,A10+1,"") -> 3 | AO14: =IF($AU$5=TRUE,AO10+1,"") -> 19
B15: 12 | C15: =Games!I7 -> Alabama State | D15: =_xlfn.XLOOKUP(C15,Teams!$C:$C,Teams!$E:$E,,0,1) -> #VALUE! | E15: =Games!N7 -> 97 | F15: =IF($AU$5=TRUE,F7+1,"") -> 34 | I15: =Games!O39 -> Alcorn State | J15: =_xlfn.XLOOKUP(I15,Teams!$C:$C,Teams!$E:$E,,0,1) -> #VALUE! | K15: =Games!N55 -> 113 | AE15: =Games!N59 -> 111 | AF15: =_xlfn.XLOOKUP(AG15,Teams!$C:$C,Teams!$E:$E,,0,1) -> #VALUE! | AG15: =Games!O47 -> Cal State Fullerton | AJ15: =IF($AU$5=TRUE,AJ7+1,"") -> 42 | AK15: =Games!N23 -> 98 | AL15: =_xlfn.XLOOKUP(AM15,Teams!$C:$C,Teams!$E:$E,,0,1) -> #VALUE! | AM15: =Games!I23 -> Cal State Fullerton | AN15: 12
B17: 4 | C17: =Games!G8 -> Albany (NY) | D17: =_xlfn.XLOOKUP(C17,Teams!$C:$C,Teams!$E:$E,,0,1) -> #VALUE! | E17: =Games!L8 -> 103 | F17: =Games!O8 -> Alcorn State | G17: =_xlfn.XLOOKUP(F17,Teams!$C:$C,Teams!$E:$E,,0,1) -> #VALUE! | H17: =Games!N39 -> 112 | AH17: =Games!N47 -> 101 | AI17: =_xlfn.XLOOKUP(AJ17,Teams!$C:$C,Teams!$E:$E,,0,1) -> #VALUE! | AJ17: =Games!O24 -> Cal State Northridge | AK17: =Games!L24 -> 110 | AL17: =_xlfn.XLOOKUP(AM17,Teams!$C:$C,Teams!$E:$E,,0,1) -> #VALUE! | AM17: =Games!G24 -> Cal State Northridge | AN17: 4
A18: =IF($AU$5=TRUE,A14+1,"") -> 4 | AO18: =IF($AU$5=TRUE,AO14+1,"") -> 20
B19: 13 | C19: =Games!I8 -> Alcorn State | D19: =_xlfn.XLOOKUP(C19,Teams!$C:$C,Teams!$E:$E,,0,1) -> #VALUE! | E19: =Games!N8 -> 109 | K19: South | O19: =Games!O64 -> American | P19: =_xlfn.XLOOKUP(O19,Teams!$C:$C,Teams!$E:$E,,0,1) -> #VALUE! | Q19: =Games!L69 -> 112 | Y19: =Games!L70 -> 97 | Z19: =_xlfn.XLOOKUP(AA19,Teams!$C:$C,Teams!$E:$E,,0,1) -> #VALUE! | AA19: =Games!O66 -> Cal Poly | AD19: East | AK19: =Games!N24 -> 108 | AL19: =_xlfn.XLOOKUP(AM19,Teams!$C:$C,Teams!$E:$E,,0,1) -> #VALUE! | AM19: =Games!I24 -> California | AN19: 13
A21: =IF($AU$5=TRUE,A18+1,"") -> 5 | B21: 6 | C21: =Games!G9 -> American | D21: =_xlfn.XLOOKUP(C21,Teams!$C:$C,Teams!$E:$E,,0,1) -> #VALUE! | E21: =Games!L9 -> 107 | F21: =Games!O9 -> American | G21: =_xlfn.XLOOKUP(F21,Teams!$C:$C,Teams!$E:$E,,0,1) -> #VALUE! | H21: =Games!L40 -> 103 | L21: =IF($AU$5=TRUE,AG59+1,"") -> 57 | AD21: =IF($AU$5=TRUE,L53+1,"") -> 59 | AH21: =Games!L48 -> 91 | AI21: =_xlfn.XLOOKUP(AJ21,Teams!$C:$C,Teams!$E:$E,,0,1) -> #VALUE! | AJ21: =Games!O25 -> Campbell | AK21: =Games!L25 -> 104 | AL21: =_xlfn.XLOOKUP(AM21,Teams!$C:$C,Teams!$E:$E,,0,1) -> #VALUE! | AM21: =Games!G25 -> California Baptist | AN21: 6
AO22: =IF($AU$5=TRUE,AO18+1,"") -> 21
B23: 11 | C23: =Games!I9 -> Appalachian State | D23: =_xlfn.XLOOKUP(C23,Teams!$C:$C,Teams!$E:$E,,0,1) -> #VALUE! | E23: =Games!N9 -> 104 | F23: =IF($AU$5=TRUE,F15+1,"") -> 35 | I23: =Games!O40 -> American | J23: =_xlfn.XLOOKUP(I23,Teams!$C:$C,Teams!$E:$E,,0,1) -> #VALUE! | K23: =Games!L56 -> 104 | AE23: =Games!L60 -> 91 | AF23: =_xlfn.XLOOKUP(AG23,Teams!$C:$C,Teams!$E:$E,,0,1) -> #VALUE! | AG23: =Games!O48 -> Central Arkansas | AJ23: =IF($AU$5=TRUE,AJ15+1,"") -> 43 | AK23: =Games!N25 -> 109 | AL23: =_xlfn.XLOOKUP(AM23,Teams!$C:$C,Teams!$E:$E,,0,1) -> #VALUE! | AM23: =Games!I25 -> Campbell | AN23: 11
B25: 3 | C25: =Games!G10 -> Arizona | D25: =_xlfn.XLOOKUP(C25,Teams!$C:$C,Teams!$E:$E,,0,1) -> #VALUE! | E25: =Games!L10 -> 117 | F25: =Games!O10 -> Arizona | G25: =_xlfn.XLOOKUP(F25,Teams!$C:$C,Teams!$E:$E,,0,1) -> #VALUE! | H25: =Games!N40 -> 97 | AH25: =Games!N48 -> 112 | AI25: =_xlfn.XLOOKUP(AJ25,Teams!$C:$C,Teams!$E:$E,,0,1) -> #VALUE! | AJ25: =Games!O26 -> Central Arkansas | AK25: =Games!L26 -> 92 | AL25: =_xlfn.XLOOKUP(AM25,Teams!$C:$C,Teams!$E:$E,,0,1) -> #VALUE! | AM25: =Games!G26 -> Canisius | AN25: 3
A26: =IF($AU$5=TRUE,A21+1,"") -> 6 | AO26: =IF($AU$5=TRUE,AO22+1,"") -> 22
B27: 14 | C27: =Games!I10 -> Arizona State | D27: =_xlfn.XLOOKUP(C27,Teams!$C:$C,Teams!$E:$E,,0,1) -> #VALUE! | E27: =Games!N10 -> 103 | I27: =IF($AU$5=TRUE,I11+1,"") -> 50 | L27: =Games!O56 -> American | M27: =_xlfn.XLOOKUP(L27,Teams!$C:$C,Teams!$E:$E,,0,1) -> #VALUE! | N27: =Games!N64 -> 109 | R27: =Games!O69 -> Auburn | U27: =_xlfn.XLOOKUP(R27,Teams!$C:$C,Teams!$E:$E,,0,1) -> #VALUE! | V27: =Games!L72 -> 119 | AB27: =Games!N66 -> 117 | AC27: =_xlfn.XLOOKUP(AD27,Teams!$C:$C,Teams!$E:$E,,0,1) -> #VALUE! | AD27: =Games!O60 -> Central Michigan | AG27: =IF($AU$5=TRUE,AG11+1,"") -> 54 | AK27: =Games!N26 -> 98 | AL27: =_xlfn.XLOOKUP(AM27,Teams!$C:$C,Teams!$E:$E,,0,1) -> #VALUE! | AM27: =Games!I26 -> Central Arkansas | AN27: 14
B29: 7 | C29: =Games!G11 -> Arkansas | D29: =_xlfn.XLOOKUP(C29,Teams!$C:$C,Teams!$E:$E,,0,1) -> #VALUE! | E29: =Games!L11 -> 99 | F29: =Games!O11 -> Arkansas State | G29: =_xlfn.XLOOKUP(F29,Teams!$C:$C,Teams!$E:$E,,0,1) -> #VALUE! | H29: =Games!L41 -> 117 | AH29: =Games!L49 -> 92 | AI29: =_xlfn.XLOOKUP(AJ29,Teams!$C:$C,Teams!$E:$E,,0,1) -> #VALUE! | AJ29: =Games!O27 -> Central Michigan | AK29: =Games!L27 -> 93 | AL29: =_xlfn.XLOOKUP(AM29,Teams!$C:$C,Teams!$E:$E,,0,1) -> #VALUE! | AM29: =Games!G27 -> Central Connecticut State | AN29: 7 | AP29: x | AQ29: Show Game Numbers
A30: =IF($AU$5=TRUE,A26+1,"") -> 7 | AO30: =IF($AU$5=TRUE,AO26+1,"") -> 23
B31: 10 | C31: =Games!I14 -> Baylor | D31: =_xlfn.XLOOKUP(C31,Teams!$C:$C,Teams!$E:$E,,0,1) -> #VALUE! | E31: =Games!N11 -> 102 | F31: =IF($AU$5=TRUE,F23+1,"") -> 36 | I31: =Games!O41 -> Arkansas State | J31: =_xlfn.XLOOKUP(I31,Teams!$C:$C,Teams!$E:$E,,0,1) -> #VALUE! | K31: =Games!N56 -> 96 | S31: National Champion | AE31: =Games!N60 -> 115 | AF31: =_xlfn.XLOOKUP(AG31,Teams!$C:$C,Teams!$E:$E,,0,1) -> #VALUE! | AG31: =Games!O49 -> Central Michigan | AJ31: =IF($AU$5=TRUE,AJ23+1,"") -> 44 | AK31: =Games!N27 -> 94 | AL31: =_xlfn.XLOOKUP(AM31,Teams!$C:$C,Teams!$E:$E,,0,1) -> #VALUE! | AM31: =Games!I27 -> Central Michigan | AN31: 10
S32: =Games!O72 -> Auburn
B33: 2 | C33: =Games!G12 -> Arkansas-Pine Bluff | D33: =_xlfn.XLOOKUP(C33,Teams!$C:$C,Teams!$E:$E,,0,1) -> #VALUE! | E33: =Games!L12 -> 104 | F33: =Games!O12 -> Army | G33: =_xlfn.XLOOKUP(F33,Teams!$C:$C,Teams!$E:$E,,0,1) -> #VALUE! | H33: =Games!N41 -> 112 | AH33: =Games!N49 -> 91 | AI33: =_xlfn.XLOOKUP(AJ33,Teams!$C:$C,Teams!$E:$E,,0,1) -> #VALUE! | AJ33: =Games!O28 -> Charlotte | AK33: =Games!L28 -> 107 | AL33: =_xlfn.XLOOKUP(AM33,Teams!$C:$C,Teams!$E:$E,,0,1) -> #VALUE! | AM33: =Games!G28 -> Charleston Southern | AN33: 2
A34: =IF($AU$5=TRUE,A30+1,"") -> 8 | AO34: =IF($AU$5=TRUE,AO30+1,"") -> 24
B35: 15 | C35: =Games!I12 -> Army | D35: =_xlfn.XLOOKUP(C35,Teams!$C:$C,Teams!$E:$E,,0,1) -> #VALUE! | E35: =Games!N12 -> 119 | O35: =IF($AU$5=TRUE,AD53+1,"") -> 61 | T35: =IF($AU$5=TRUE,AA35+1,"") -> 63 | AA35: =IF($AU$5=TRUE,O35+1,"") -> 62 | AK35: =Games!N28 -> 120 | AL35: =_xlfn.XLOOKUP(AM35,Teams!$C:$C,Teams!$E:$E,,0,1) -> #VALUE! | AM35: =Games!I28 -> Charlotte | AN35: 15
B37: 1 | C37: =Games!G13 -> Auburn | D37: =_xlfn.XLOOKUP(C37,Teams!$C:$C,Teams!$E:$E,,0,1) -> #VALUE! | E37: =Games!L13 -> 117 | F37: =Games!O13 -> Auburn | G37: =_xlfn.XLOOKUP(F37,Teams!$C:$C,Teams!$E:$E,,0,1) -> #VALUE! | H37: =Games!L42 -> 106 | AH37: =Games!L50 -> 116 | AI37: =_xlfn.XLOOKUP(AJ37,Teams!$C:$C,Teams!$E:$E,,0,1) -> #VALUE! | AJ37: =Games!O29 -> Chattanooga | AK37: =Games!L29 -> 112 | AL37: =_xlfn.XLOOKUP(AM37,Teams!$C:$C,Teams!$E:$E,,0,1) -> #VALUE! | AM37: =Games!G29 -> Chattanooga | AN37: 1
A38: =IF($AU$5=TRUE,A34+1,"") -> 9 | AO38: =IF($AU$5=TRUE,AO34+1,"") -> 25
B39: 16 | C39: =Games!I13 -> Austin Peay | D39: =_xlfn.XLOOKUP(C39,Teams!$C:$C,Teams!$E:$E,,0,1) -> #VALUE! | E39: =Games!N13 -> 111 | F39: =IF($AU$5=TRUE,F31+1,"") -> 37 | I39: =Games!O42 -> Auburn | J39: =_xlfn.XLOOKUP(I39,Teams!$C:$C,Teams!$E:$E,,0,1) -> #VALUE! | K39: =Games!L57 -> 120 | T39: =Games!N72 -> 96 | U39: =_xlfn.XLOOKUP(V39,Teams!$C:$C,Teams!$E:$E,,0,1) -> #VALUE! | V39: =Games!O70 -> Cleveland State | AE39: =Games!L61 -> 91 | AF39: =_xlfn.XLOOKUP(AG39,Teams!$C:$C,Teams!$E:$E,,0,1) -> #VALUE! | AG39: =Games!O50 -> Chattanooga | AJ39: =IF($AU$5=TRUE,AJ31+1,"") -> 45 | AK39: =Games!N29 -> 104 | AL39: =_xlfn.XLOOKUP(AM39,Teams!$C:$C,Teams!$E:$E,,0,1) -> #VALUE! | AM39: =Games!I29 -> Chicago State | AN39: 16
B41: 8 | C41: =Games!G14 -> Ball State | D41: =_xlfn.XLOOKUP(C41,Teams!$C:$C,Teams!$E:$E,,0,1) -> #VALUE! | E41: =Games!L14 -> 105 | F41: =Games!O14 -> Baylor | G41: =_xlfn.XLOOKUP(F41,Teams!$C:$C,Teams!$E:$E,,0,1) -> #VALUE! | H41: =Games!N42 -> 90 | AH41: =Games!N50 -> 91 | AI41: =_xlfn.XLOOKUP(AJ41,Teams!$C:$C,Teams!$E:$E,,0,1) -> #VALUE! | AJ41: =Games!O30 -> Clemson | AK41: =Games!L30 -> 91 | AL41: =_xlfn.XLOOKUP(AM41,Teams!$C:$C,Teams!$E:$E,,0,1) -> #VALUE! | AM41: =Games!G30 -> Cincinnati | AN41: 8
A42: =IF($AU$5=TRUE,A38+1,"") -> 10 | AO42: =IF($AU$5=TRUE,AO38+1,"") -> 26
B43: 9 | C43: =Games!I14 -> Baylor | D43: =_xlfn.XLOOKUP(C43,Teams!$C:$C,Teams!$E:$E,,0,1) -> #VALUE! | E43: =Games!N14 -> 109 | I43: =IF($AU$5=TRUE,I27+1,"") -> 51 | L43: =Games!O57 -> Auburn | M43: =_xlfn.XLOOKUP(L43,Teams!$C:$C,Teams!$E:$E,,0,1) -> #VALUE! | N43: =Games!L65 -> 103 | AB43: =Games!L67 -> 109 | AC43: =_xlfn.XLOOKUP(AD43,Teams!$C:$C,Teams!$E:$E,,0,1) -> #VALUE! | AD43: =Games!O61 -> Cleveland State | AG43: =IF($AU$5=TRUE,AG27+1,"") -> 55 | AK43: =Games!N30 -> 112 | AL43: =_xlfn.XLOOKUP(AM43,Teams!$C:$C,Teams!$E:$E,,0,1) -> #VALUE! | AM43: =Games!I30 -> Clemson | AN43: 9
B45: 5 | C45: =Games!G15 -> Bellarmine | D45: =_xlfn.XLOOKUP(C45,Teams!$C:$C,Teams!$E:$E,,0,1) -> #VALUE! | E45: =Games!L15 -> 99 | F45: =Games!O15 -> Belmont | G45: =_xlfn.XLOOKUP(F45,Teams!$C:$C,Teams!$E:$E,,0,1) -> #VALUE! | H45: =Games!L43 -> 95 | AH45: =Games!L51 -> 116 | AI45: =_xlfn.XLOOKUP(AJ45,Teams!$C:$C,Teams!$E:$E,,0,1) -> #VALUE! | AJ45: =Games!O31 -> Cleveland State | AK45: =Games!L31 -> 108 | AL45: =_xlfn.XLOOKUP(AM45,Teams!$C:$C,Teams!$E:$E,,0,1) -> #VALUE! | AM45: =Games!G31 -> Cleveland State | AN45: 5
A46: =IF($AU$5=TRUE,A42+1,"") -> 11 | AO46: =IF($AU$5=TRUE,AO42+1,"") -> 27
B47: 12 | C47: =Games!I15 -> Belmont | D47: =_xlfn.XLOOKUP(C47,Teams!$C:$C,Teams!$E:$E,,0,1) -> #VALUE! | E47: =Games!N15 -> 111 | F47: =IF($AU$5=TRUE,F39+1,"") -> 38 | I47: =Games!O43 -> Binghamton | J47: =_xlfn.XLOOKUP(I47,Teams!$C:$C,Teams!$E:$E,,0,1) -> #VALUE! | K47: =Games!N57 -> 111 | AE47: =Games!N61 -> 112 | AF47: =_xlfn.XLOOKUP(AG47,Teams!$C:$C,Teams!$E:$E,,0,1) -> #VALUE! | AG47: =Games!O51 -> Cleveland State | AJ47: =IF($AU$5=TRUE,AJ39+1,"") -> 46 | AK47: =Games!N31 -> 107 | AL47: =_xlfn.XLOOKUP(AM47,Teams!$C:$C,Teams!$E:$E,,0,1) -> #VALUE! | AM47: =Games!I31 -> Coastal Carolina | AN47: 12
B49: 4 | C49: =Games!G16 -> Bethune-Cookman | D49: =_xlfn.XLOOKUP(C49,Teams!$C:$C,Teams!$E:$E,,0,1) -> #VALUE! | E49: =Games!L16 -> 99 | F49: =Games!O16 -> Binghamton | G49: =_xlfn.XLOOKUP(F49,Teams!$C:$C,Teams!$E:$E,,0,1) -> #VALUE! | H49: =Games!N43 -> 115 | AH49: =Games!N51 -> 112 | AI49: =_xlfn.XLOOKUP(AJ49,Teams!$C:$C,Teams!$E:$E,,0,1) -> #VALUE! | AJ49: =Games!O32 -> College of Charleston | AK49: =Games!L32 -> 98 | AL49: =_xlfn.XLOOKUP(AM49,Teams!$C:$C,Teams!$E:$E,,0,1) -> #VALUE! | AM49: =Games!G32 -> Colgate | AN49: 4
A50: =IF($AU$5=TRUE,A46+1,"") -> 12 | AO50: =IF($AU$5=TRUE,AO46+1,"") -> 28
B51: 13 | C51: =Games!I16 -> Binghamton | D51: =_xlfn.XLOOKUP(C51,Teams!$C:$C,Teams!$E:$E,,0,1) -> #VALUE! | E51: =Games!N16 -> 117 | K51: West | O51: =Games!O65 -> Auburn | P51: =_xlfn.XLOOKUP(O51,Teams!$C:$C,Teams!$E:$E,,0,1) -> #VALUE! | Q51: =Games!N69 -> 116 | Y51: =Games!N70 -> 120 | Z51: =_xlfn.XLOOKUP(AA51,Teams!$C:$C,Teams!$E:$E,,0,1) -> #VALUE! | AA51: =Games!O67 -> Cleveland State | AD51: Midwest | AK51: =Games!N32 -> 118 | AL51: =_xlfn.XLOOKUP(AM51,Teams!$C:$C,Teams!$E:$E,,0,1) -> #VALUE! | AM51: =Games!I32 -> College of Charleston | AN51: 13
...
